Workbook

Sheet Instrucciones
A1: GUÍA PARA USAR ESTE MODELO EN GOOGLE SHEETS
A2: ACS Ingeniería Constructora S.A.S. · Rincón del Bosque II · Leé esto antes de empezar
A4: 1) CÓMO SUBIRLO A GOOGLE SHEETS
A5: 1. Google Drive - Nuevo - Subir archivo - elegí este .xlsx.
A6: 2. Clic derecho sobre el archivo - Abrir con - Hojas de cálculo de Google.
A7: 3. Archivo - Guardar como Hojas de cálculo de Google (editable online y compartible).
A8: 4. Trabajás la copia de Google; el .xlsx queda de respaldo.
A10: 2) DÓLAR - ACTUALIZACIÓN AUTOMÁTICA
A11: El dólar está en la hoja Resumen, celda G6 (hoy a mano en 1515).
A12: Para que se actualice solo, copiá una de estas fórmulas en G6:
A14: DÓLAR OFICIAL (confiable):
A15: FÓRMULA: =GOOGLEFINANCE("CURRENCY:USDARS")
... A38: - Cambiás G6 y se recalcula todo el modelo.

Sheet Resumen
A1: MODELO DE PROYECTO — RINCÓN DEL BOSQUE II (VERSIÓN GOOGLE SHEETS)
A2: ACS Ingeniería Constructora S.A.S. · Panel de control exclusivo de RDB II · 3 sectores (Sector 1, Sector Sur, Mangrullo Este)
A3: =HYPERLINK("#'Resumen'!A1","📊 Resumen") -> 📊 Resumen | C3: =HYPERLINK("#'MaestroLotes'!A1","🏘 Lotes") -> 🏘 Lotes | E3: =HYPERLINK("#'Clientes'!A1","👥 Clientes") -> 👥 Clientes | G3: =HYPERLINK("#'DetalleCostos'!A1","🧾 Costos") -> 🧾 Costos | I3: =HYPERLINK("#'FlujoCaja'!A1","💰 Flujo") -> 💰 Flujo
A5: DATOS DEL PROYECTO | P5: DÓLAR AUTO (Google Sheets)
A6: Nombre del Proyecto | B6: Rincón del Bosque II — Familia Maler | F6: Valor Dólar (ARS) | G6: 1515 | P6: Pegá en Resumen!G6 para dólar oficial auto:
A7: Ubicación | F7: Fecha de Inicio | P7: FÓRMULA: =GOOGLEFINANCE("CURRENCY:USDARS")
A8: Responsable | B8: ACS INGENIERÍA CONSTRUCTORA S-A-S / Vaccaro Nicolas Augusto | F8: Fecha Estimada Fin | G8: 2027 - 01 | P8: Para blue: ver hoja Instrucciones
A9: N° de Plano / Mensura | B9: 223-24 | F9: Estado del Proyecto | G9: En Curso
A11: INDICADORES CONSOLIDADOS DEL PROYECTO | P11: Anticipo | S11: 0.5
A12: 🏘 INVENTARIO DE LOTES COMPLETOS | P12: Cuotas (cantidad) | S12: 12
A13: Parcelas madres a comercializar (-2 Ludgardo - 1 RF- 1AV, total Mº 49) | E13: Madres con oferta activa | I13: Lotes vendidos (total) | P13: CAC mensual estim. | S13: 0.03
A14: =SUMPRODUCT(--ISNUMBER(MaestroLotes!E6:E145))-SUMPRODUCT(--ISNUMBER(MaestroLotes!E6:E145)*ISNUMBER(SEARCH("Dominio público",MaestroLotes!J6:J145&""))) -> 43 | E14: =SUMPRODUCT(--ISNUMBER(MaestroLotes!E6:E145)*(MaestroLotes!I6:I145="Disponible")) -> 28 | I14: =SUMPRODUCT((MaestroLotes!I6:I145="VendidoP.C")*((MaestroLotes!N6:N145="Madre")+(MaestroLotes!N6:N145="Completa"))) -> 0
A15: sin dominio público (P20) · cada madre = 1 lote | E15: madres con unidades a la venta | I15: P12-P13 enteros · P14-P15 por 2/2 UF
A16: Permutadas | E16: No comerciales | I16: Total lotes completos activos | O16: =SUMPRODUCT(--ISNUMBER(MaestroLotes!E6:E145)*(MaestroLotes!I6:I145="Disponible")) -> 28
A17: =COUNTIF(MaestroLotes!I6:I145,"Permutada") -> 10 | E17: =SUMPRODUCT(--ISNUMBER(MaestroLotes!E6:E145)*(MaestroLotes!I6:I145="No comercial")) -> 6 | I17: =A14-SUMPRODUCT(--ISNUMBER(MaestroLotes!E6:E145)*(MaestroLotes!I6:I145="Permutada"))-SUMPRODUCT(--ISNUMBER(MaestroLotes!E6:E145)*(MaestroLotes!I6:I145="No comercial")*ISERROR(SEARCH("Dominio público",MaestroLotes!J6:J145&""))) -> 33 | P17: =SUMPRODUCT(--ISNUMBER(MaestroLotes!E6:E145)*(MaestroLotes!I6:I145="No comercial")) -> 6
Q18: =COUNTIF(MaestroLotes!I6:I145,"Permutada") -> 10
A19: 🔢 INVENTARIO DE FRACCIONAMIENTO EN UF (parcelas de 450 m² promedio)
A20: UF disponibles | E20: UF vendidas | I20: UF totales en listado
A21: =SUMPRODUCT((MaestroLotes!I6:I145="Disponible")*(MaestroLotes!N6:N145="UF")) -> 50 | E21: =SUMPRODUCT((MaestroLotes!I6:I145="Vendido")*(MaestroLotes!N6:N145="UF")) -> 0 | I21: =SUMPRODUCT((MaestroLotes!N6:N145="UF")*(MaestroLotes!I6:I145<>"")*(MaestroLotes!I6:I145<>"No comercial")) -> 117
A24: 💰 VENTAS, COSTOS Y RESULTADO
A25: VENTA BRUTA (USD) | E25: COSTOS NETOS ESTIMADOS (USD) OBRA TOTAL + % DE COMISIÓN Y HONORARIOS | I25: GANANCIA NETA ESTIMADA (USD)
A26: =MaestroLotes!G137 -> 1619103.9 | E26: =(A34)+(A26*4%) -> 447914.41 | I26: =A26-E26 -> 1171189.5
A28: Ganancia Neta Ventas Actuales | E28: Cobrado dueños (USD) | I28: Saldo por Cobrar (USD)
A29: =SUM(Clientes!M5:M34) -> 100330 | E29: 2000000 | I29: =SUM(Clientes!K5:K34) -> 7755
E30: ingresado a caja
A33: Total Presupuesto (USD) SI,II,III
A34: =DetalleCostos!$E$22 -> 383150.25 | C34: =DetalleCostos!$F$22 -> 242000 | E34: =DetalleCostos!$G$22 -> 225150 | G34: =DetalleCostos!$H$22 -> 77500 | I34: =DetalleCostos!$I$22 -> 147650
A35: 100% del proyecto | C35: cubierto con lotes | E35: necesario en efectivo | G35: ya pagado | I35: falta pagar
A45: 💳 VENTA FINANCIADA (anticipo 50% + 12 cuotas ajustadas por CAC) — sobre lotes disponibles
A46: Total Anticipos 50% (USD) | E46: Total Cuotas c/ CAC (USD) | I46: TOTAL A RECAUDAR Financiado (USD)
A47: =(A26-A29)/2 -> 759386.97 | E47: =SUMIFS(MaestroLotes!$Q$6:$Q$145,MaestroLotes!$I$6:$I$145,"Disponible") -> 305872.76 | I47: =SUMIFS(MaestroLotes!$R$6:$R$145,MaestroLotes!$I$6:$I$145,"Disponible") -> 556969.06
A48: si se venden todos los disponibles | E48: 12 cuotas ajustadas | I48: anticipos + cuotas
A49: Valor Contado disponibles (USD) | E49: Extra por financiación (USD) | I49: % Incremento financiado
A50: =SUMIFS(MaestroLotes!$G$6:$G$145,MaestroLotes!$I$6:$I$145,"Disponible") -> 502192.6 | E50: =SUMIFS(MaestroLotes!$R$6:$R$145,MaestroLotes!$I$6:$I$145,"Disponible")-SUMIFS(MaestroLotes!$G$6:$G$145,MaestroLotes!$I$6:$I$145,"Disponible") -> 54776.458 | I50: =IFERROR(SUMIFS(MaestroLotes!$R$6:$R$145,MaestroLotes!$I$6:$I$145,"Disponible")/SUMIFS(MaestroLotes!$G$6:$G$145,MaestroLotes!$I$6:$I$145,"Disponible")-1,0) -> 0.1090746
A51: precio de lista

Sheet MaestroLotes
A1: 🏘 MAESTRO DE LOTES — RDB II · PARCELA MADRE + UNIDADES FUNCIONALES
A3: =HYPERLINK("#'Resumen'!A1","◀ Volver al Resumen") -> ◀ Volver al Resumen | D3: ="Completos disp: "&SUMPRODUCT((I6:I148="Disponible")*ISERROR(SEARCH("UF",C6:C148)))&" | UF disp: "&SUMPRODUCT((I6:I148="Disponible")*ISNUMBER(SEARCH("UF",C6:C148)))&" | Vendidos: "&COUNTIF(I6:I148,"Vendido")&" | Permutadas: "&COUNTIF(I6:I148,"Permutada")&" | Fondeo: "&COUNTIF(I6:I148,"Fondeo") -> Completos disp: 30 | UF disp: 20 | Vendidos: 0 | Permutadas: 10 | Fondeo: 0
A4: Sector | B4: Parcela Madre | C4: Unidad / Subdiv. | D4: Nomenclatura Catastral | E4: Sup. Oficial (m²) | F4: Sup. Comercial (m²) | G4: Precio Lista (USD) | H4: Precio Lista (ARS) | I4: Estado | J4: Cliente Asignado | K4: Contrato N° | L4: Saldo Pend. | M4: Escriturado | N4: Tipo | O4: Anticipo 50% (USD) | P4: Valor Cuota inicial (USD) | Q4: Total 12 Cuotas c/ CAC (USD) | R4: TOTAL Financiado (USD) | S4: UF eq. | T4: PLANTAR VALOR $/m²
A5: ▼ SECTOR I — Chacra 08 - P8 a 22
A6: SECTOR 1 | B6: P8 | C6: PARCELA MADRE | D6: 24-2-3-Ch8-P8 | E6: 2699.72 | H6: =IF(G6="","",G6*Resumen!$G$6) | I6: =IF(H6="","",H6*Resumen!$G$6) | L6: 0 | M6: — | N6: UF | O6: =IF(G6="","",G6*Resumen!$S$11) | P6: =IF(G6="","",(G6-G6*Resumen!$S$11)/Resumen!$S$12) | Q6: =IF(G6="","",((G6-G6*Resumen!$S$11)/Resumen!$S$12)*((1+Resumen!$S$13)*((1+Resumen!$S$13)^Resumen!$S$12-1)/Resumen!$S$13)) | R6: =IF(G6="","",O6+Q6) | S6: 6 | T6: UF Sector 1 / Sur | U6: 36.6667
A7: SECTOR 1 | B7: P8 | C7: PARCELA MADRE UF | D7: 24-2-3-Ch8-P8D | I7: Permutada | J7: Albornoz | L7: 0 | M7: — | N7: UF | S7: 6 | T7: UF Sector 1 / Sur | U7: 36.6667
A8: SECTOR 1 | B8: P8 | C8: PARCELA MADRE UF | D8: 24-2-3-Ch8-P8C | E8: 900 | F8: 900 | G8: 20000 | H8: =IF(G8="","",G8*Resumen!$G$6) -> 30300000 | I8: Disponible UF | L8: 0 | M8: — | N8: UF | O8: =IF(G8="","",G8*Resumen!$S$11) -> 10000 | P8: =IF(G8="","",(G8-G8*Resumen!$S$11)/Resumen!$S$12) -> 833.33333 | Q8: =IF(G8="","",((G8-G8*Resumen!$S$11)/Resumen!$S$12)*((1+Resumen!$S$13)*((1+Resumen!$S$13)^Resumen!$S$12-1)/Resumen!$S$13)) -> 12181.492 | R8: =IF(G8="","",O8+Q8) -> 22181.492 | T8: Entera 900 / Fondeo | U8: 33.3333
A9: SECTOR 1 | B9: P8 | C9: PARCELA MADRE UF | D9: 24-2-3-Ch8-P8A | E9: 900 | F9: 900 | G9: =30000/F9 -> 33.333333 | H9: =IF(G9="","",G9*Resumen!$G$6) -> 50500 | I9: Disponible UF | L9: - | M9: - | N9: UF
A10: SECTOR 1 | B10: P8 | C10: UF A | D10: 24-2-3-Ch8-P8-M900C-UFA | F10: 450 | G10: =ROUND(F10*$U$6,0) -> 16500 | H10: =IF(G10="","",G10*Resumen!$G$6) -> 24997500 | I10: Disponible UF | L10: - | M10: - | N10: UF | O10: =IF(G10="","",G10*Resumen!$S$11) -> 8250 | P10: =IF(G10="","",(G10-G10*Resumen!$S$11)/Resumen!$S$12) -> 687.5 | Q10: =IF(G10="","",((G10-G10*Resumen!$S$11)/Resumen!$S$12)*((1+Resumen!$S$13)*((1+Resumen!$S$13)^Resumen!$S$12-1)/Resumen!$S$13)) -> 10049.731 | R10: =IF(G10="","",O10+Q10) -> 18299.731 | T10: Entera Mza13 (referencia) | U10: 25
A11: SECTOR 1 | B11: P8 | C11: UF B | D11: 24-2-3-Ch8-P8-M900C-UFB | F11: 450 | G11: =ROUND(F11*$U$6,0) -> 16500 | H11: =IF(G11="","",G11*Resumen!$G$6) -> 24997500 | I11: Disponible UF | L11: - | M11: - | N11: UF | O11: =IF(G11="","",G11*Resumen!$S$11) -> 8250 | P11: =IF(G11="","",(G11-G11*Resumen!$S$11)/Resumen!$S$12) -> 687.5 | Q11: =IF(G11="","",((G11-G11*Resumen!$S$11)/Resumen!$S$12)*((1+Resumen!$S$13)*((1+Resumen!$S$13)^Resumen!$S$12-1)/Resumen!$S$13)) -> 10049.731 | R11: =IF(G11="","",O11+Q11) -> 18299.731 | T11: Editá estas celdas y toda la tabla, los totales y el dashboard se recalculan solos. Precios vendidos, permutas y valores fijos (P9+P10, casa) no se tocan.
A12: SECTOR 1 | B12: P9 | C12: Completa | D12: 24-2-3-Ch8-P9 | E12: 900 | F12: 900 | G12: =F12*33 -> 29700 | H12: =IF(G12="","",G12*Resumen!$G$6) -> 44995500 | I12: Disponible | L12: 0 | M12: — | N12: UF | O12: =IF(G12="","",G12*Resumen!$S$11) -> 14850 | P12: =IF(G12="","",(G12-G12*Resumen!$S$11)/Resumen!$S$12) -> 1237.5 | Q12: =IF(G12="","",((G12-G12*Resumen!$S$11)/Resumen!$S$12)*((1+Resumen!$S$13)*((1+Resumen!$S$13)^Resumen!$S$12-1)/Resumen!$S$13)) -> 18089.516 | R12: =IF(G12="","",O12+Q12) -> 32939.516 | S12: 2
A13: SECTOR 1 | B13: P10 | C13: Completa | D13: 24-2-3-Ch8-P10 | E13: 1280.12 | F13: 1280.12 | G13: =F13*30 -> 38403.6 | H13: =IF(G13="","",G13*Resumen!$G$6) -> 58181454 | I13: Disponible | L13: 0 | M13: — | N13: UF | O13: =IF(G13="","",G13*Resumen!$S$11) -> 19201.8 | P13: =IF(G13="","",(G13-G13*Resumen!$S$11)/Resumen!$S$12) -> 1600.15 | Q13: =IF(G13="","",((G13-G13*Resumen!$S$11)/Resumen!$S$12)*((1+Resumen!$S$13)*((1+Resumen!$S$13)^Resumen!$S$12-1)/Resumen!$S$13)) -> 23390.657 | R13: =IF(G13="","",O13+Q13) -> 42592.457 | S13: 2
A14: SECTOR 1 | B14: P11 | C14: Completa | D14: 24-2-3-Ch8-P10 | H14: =IF(G14="","",G14*Resumen!$G$6) | I14: Permutada | J14: Nico Gestión / Flia Santoro | L14: 0 | M14: — | N14: UF | O14: =IF(G14="","",G14*Resumen!$S$11) | P14: =IF(G14="","",(G14-G14*Resumen!$S$11)/Resumen!$S$12) | Q14: =IF(G14="","",((G14-G14*Resumen!$S$11)/Resumen!$S$12)*((1+Resumen!$S$13)*((1+Resumen!$S$13)^Resumen!$S$12-1)/Resumen!$S$13)) | R14: =IF(G14="","",O14+Q14) | S14: 2
A15: SECTOR 1 | B15: P12 | C15: PARCELA MADRE | D15: 24-2-3-Ch8-P12 | E15: 940.26 | F15: 900 | G15: 28000 | H15: =IF(G15="","",G15*Resumen!$G$6) -> 42420000 | I15: Vendido P.C | J15: Moreira (Analia y Casi) | K15: BOL-012 | L15: 0 | M15: - | N15: UF | O15: - | P15: - | Q15: - | R15: - | S15: 2
A16: SECTOR 1 | B16: P13 | C16: PARCELA MADRE | D16: 24-2-3-Ch8-P13 | E16: 934.32 | F16: 900 | G16: 28000 | H16: =IF(G16="","",G16*Resumen!$G$6) -> 42420000 | I16: Vendido P.C | J16: Daddona (Luciano y Natalia) | K16: BOL-013 | L16: 0 | M16: NO | N16: UF | O16: =IF(G16="","",G16*Resumen!$S$11) -> 14000 | P16: =IF(G16="","",(G16-G16*Resumen!$S$11)/Resumen!$S$12) -> 1166.6667 | Q16: =IF(G16="","",((G16-G16*Resumen!$S$11)/Resumen!$S$12)*((1+Resumen!$S$13)*((1+Resumen!$S$13)^Resumen!$S$12-1)/Resumen!$S$13)) -> 17054.089 | R16: =IF(G16="","",O16+Q16) -> 31054.089 | S16: 2
A17: SECTOR 1 | B17: P14 | C17: PARCELA MADRE | D17: 24-2-3-Ch8-P14 | H17: =IF(G17="","",G17*Resumen!$G$6) | I17: Vendido UF | N17: UF | O17: =IF(G17="","",G17*Resumen!$S$11) | P17: =IF(G17="","",(G17-G17*Resumen!$S$11)/Resumen!$S$12) | Q17: =IF(G17="","",((G17-G17*Resumen!$S$11)/Resumen!$S$12)*((1+Resumen!$S$13)*((1+Resumen!$S$13)^Resumen!$S$12-1)/Resumen!$S$13)) | R17: =IF(G17="","",O17+Q17) | S17: 2
A18: SECTOR 1 | B18: P14 | C18: UF A | D18: 24-2-3-Ch8-P14-UFA | E18: - | F18: 465 | G18: 14000 | H18: =IF(G18="","",G18*Resumen!$G$6) -> 21210000 | I18: Vendido UF | J18: Virginia | K18: BOL-014A | L18: 0 | M18: NO | N18: UF | O18: =IF(G18="","",G18*Resumen!$S$11) -> 7000 | P18: =IF(G18="","",(G18-G18*Resumen!$S$11)/Resumen!$S$12) -> 583.33333 | Q18: =IF(G18="","",((G18-G18*Resumen!$S$11)/Resumen!$S$12)*((1+Resumen!$S$13)*((1+Resumen!$S$13)^Resumen!$S$12-1)/Resumen!$S$13)) -> 8527.0444 | R18: =IF(G18="","",O18+Q18) -> 15527.044
A19: SECTOR 1 | B19: P14 | C19: UF B | D19: 24-2-3-Ch8-P14-UFB | E19: - | F19: 465 | G19: 16000 | H19: =IF(G19="","",G19*Resumen!$G$6) -> 24240000 | I19: Vendido UF | J19: Mariel | K19: BOL-014B | L19: 7760 | M19: NO | N19: UF | O19: =IF(G19="","",G19*Resumen!$S$11) -> 8000 | P19: =IF(G19="","",(G19-G19*Resumen!$S$11)/Resumen!$S$12) -> 666.66667 | Q19: =IF(G19="","",((G19-G19*Resumen!$S$11)/Resumen!$S$12)*((1+Resumen!$S$13)*((1+Resumen!$S$13)^Resumen!$S$12-1)/Resumen!$S$13)) -> 9745.1936 | R19: =IF(G19="","",O19+Q19) -> 17745.194
A20: SECTOR 1 | B20: P16 | C20: PARCELA MADRE | D20: 24-2-3-Ch8-P16 | E20: 972.8 | H20: =IF(G20="","",G20*Resumen!$G$6) | I20: Disponible | L20: 0 | M20: — | N20: UF | O20: =IF(G20="","",G20*Resumen!$S$11) | P20: =IF(G20="","",(G20-G20*Resumen!$S$11)/Resumen!$S$12) | Q20: =IF(G20="","",((G20-G20*Resumen!$S$11)/Resumen!$S$12)*((1+Resumen!$S$13)*((1+Resumen!$S$13)^Resumen!$S$12-1)/Resumen!$S$13)) | R20: =IF(G20="","",O20+Q20) | S20: 2
A21: SECTOR 1 | B21: P15 | C21: UF A | D21: 24-2-3-Ch8-P15-UFA | F21: 492.5 | G21: 16000 | H21: =IF(G21="","",G21*Resumen!$G$6) -> 24240000 | I21: Vendido UF | J21: Santoro Demian Iván | L21: 0 | M21: — | N21: UF | O21: =IF(G21="","",G21*Resumen!$S$11) -> 8000 | P21: =IF(G21="","",(G21-G21*Resumen!$S$11)/Resumen!$S$12) -> 666.66667 | Q21: =IF(G21="","",((G21-G21*Resumen!$S$11)/Resumen!$S$12)*((1+Resumen!$S$13)*((1+Resumen!$S$13)^Resumen!$S$12-1)/Resumen!$S$13)) -> 9745.1936 | R21: =IF(G21="","",O21+Q21) -> 17745.194
A22: SECTOR 1 | B22: P15 | C22: UF B | D22: 24-2-3-Ch8-P15-UFB | F22: 492.5 | G22: 16000 | H22: =IF(G22="","",G22*Resumen!$G$6) -> 24240000 | I22: Vendido UF | J22: Michael (a liquidar) | K22: BOL-015B | L22: 0 | M22: NO | N22: UF | O22: =IF(G22="","",G22*Resumen!$S$11) -> 8000 | P22: =IF(G22="","",(G22-G22*Resumen!$S$11)/Resumen!$S$12) -> 666.66667 | Q22: =IF(G22="","",((G22-G22*Resumen!$S$11)/Resumen!$S$12)*((1+Resumen!$S$13)*((1+Resumen!$S$13)^Resumen!$S$12-1)/Resumen!$S$13)) -> 9745.1936 | R22: =IF(G22="","",O22+Q22) -> 17745.194
A23: SECTOR 1 | B23: P16 | C23: PARCELA MADRE | D23: 24-2-3-Ch8-P16 | E23: 972.8 | H23: =IF(G23="","",G23*Resumen!$G$6) | I23: Disponible | L23: 0 | M23: — | N23: UF | O23: =IF(G23="","",G23*Resumen!$S$11) | P23: =IF(G23="","",(G23-G23*Resumen!$S$11)/Resumen!$S$12) | Q23: =IF(G23="","",((G23-G23*Resumen!$S$11)/Resumen!$S$12)*((1+Resumen!$S$13)*((1+Resumen!$S$13)^Resumen!$S$12-1)/Resumen!$S$13)) | R23: =IF(G23="","",O23+Q23) | S23: 2
A24: SECTOR 1 | B24: P16 | C24: UF A | D24: 24-2-3-Ch8-P16-UFA | F24: 486.4 | G24: =ROUND(F24*$U$6,0) -> 17835 | H24: =IF(G24="","",G24*Resumen!$G$6) -> 27020025 | I24: Disponible UF | M24: — | N24: UF | O24: =IF(G24="","",G24*Resumen!$S$11) -> 8917.5 | P24: =IF(G24="","",(G24-G24*Resumen!$S$11)/Resumen!$S$12) -> 743.125 | Q24: =IF(G24="","",((G24-G24*Resumen!$S$11)/Resumen!$S$12)*((1+Resumen!$S$13)*((1+Resumen!$S$13)^Resumen!$S$12-1)/Resumen!$S$13)) -> 10862.846 | R24: =IF(G24="","",O24+Q24) -> 19780.346
A25: SECTOR 1 | B25: P16 | C25: UF B | D25: 24-2-3-Ch8-P16-UFB | F25: 486.4 | G25: =ROUND(F25*$U$6,0) -> 17835 | H25: =IF(G25="","",G25*Resumen!$G$6) -> 27020025 | I25: Disponible UF | M25: — | N25: UF | O25: =IF(G25="","",G25*Resumen!$S$11) -> 8917.5 | P25: =IF(G25="","",(G25-G25*Resumen!$S$11)/Resumen!$S$12) -> 743.125 | Q25: =IF(G25="","",((G25-G25*Resumen!$S$11)/Resumen!$S$12)*((1+Resumen!$S$13)*((1+Resumen!$S$13)^Resumen!$S$12-1)/Resumen!$S$13)) -> 10862.846 | R25: =IF(G25="","",O25+Q25) -> 19780.346
A26: SECTOR 1 | B26: P17 | C26: PARCELA MADRE | D26: 24-2-3-Ch8-P17 | E26: 1034.47 | H26: =IF(G26="","",G26*Resumen!$G$6) | I26: Disponible | L26: 0 | M26: — | N26: UF | O26: =IF(G26="","",G26*Resumen!$S$11) | P26: =IF(G26="","",(G26-G26*Resumen!$S$11)/Resumen!$S$12) | Q26: =IF(G26="","",((G26-G26*Resumen!$S$11)/Resumen!$S$12)*((1+Resumen!$S$13)*((1+Resumen!$S$13)^Resumen!$S$12-1)/Resumen!$S$13)) | R26: =IF(G26="","",O26+Q26) | S26: 2
A27: SECTOR 1 | B27: P17 | C27: UF A | D27: 24-2-3-Ch8-P17-UFA | E27: — | F27: 517.24 | G27: =ROUND(F27*$U$6,0) -> 18965 | H27: =IF(G27="","",G27*Resumen!$G$6) -> 28731975 | I27: Disponible UF | L27: 0 | M27: — | N27: UF | O27: =IF(G27="","",G27*Resumen!$S$11) -> 9482.5 | P27: =IF(G27="","",(G27-G27*Resumen!$S$11)/Resumen!$S$12) -> 790.20833 | Q27: =IF(G27="","",((G27-G27*Resumen!$S$11)/Resumen!$S$12)*((1+Resumen!$S$13)*((1+Resumen!$S$13)^Resumen!$S$12-1)/Resumen!$S$13)) -> 11551.1 | R27: =IF(G27="","",O27+Q27) -> 21033.6
A28: SECTOR 1 | B28: P17 | C28: UF B | D28: 24-2-3-Ch8-P17-UFB | E28: — | F28: 517.24 | G28: =ROUND(F28*$U$6,0) -> 18965 | H28: =IF(G28="","",G28*Resumen!$G$6) -> 28731975 | I28: Disponible UF | L28: 0 | M28: — | N28: UF | O28: =IF(G28="","",G28*Resumen!$S$11) -> 9482.5 | P28: =IF(G28="","",(G28-G28*Resumen!$S$11)/Resumen!$S$12) -> 790.20833 | Q28: =IF(G28="","",((G28-G28*Resumen!$S$11)/Resumen!$S$12)*((1+Resumen!$S$13)*((1+Resumen!$S$13)^Resumen!$S$12-1)/Resumen!$S$13)) -> 11551.1 | R28: =IF(G28="","",O28+Q28) -> 21033.6
A29: SECTOR 1 | B29: P18 | C29: PARCELA MADRE | D29: 24-2-3-Ch8-P18 | E29: 1027.67 | H29: =IF(G29="","",G29*Resumen!$G$6) | I29: Disponible | L29: 0 | M29: — | N29: UF | O29: =IF(G29="","",G29*Resumen!$S$11) | P29: =IF(G29="","",(G29-G29*Resumen!$S$11)/Resumen!$S$12) | Q29: =IF(G29="","",((G29-G29*Resumen!$S$11)/Resumen!$S$12)*((1+Resumen!$S$13)*((1+Resumen!$S$13)^Resumen!$S$12-1)/Resumen!$S$13)) | R29: =IF(G29="","",O29+Q29) | S29: 2
A30: SECTOR 1 | B30: P18 | C30: UF A | D30: 24-2-3-Ch8-P18-UFA | E30: — | F30: 513.84 | G30: =ROUND(F30*$U$6,0) -> 18841 | H30: =IF(G30="","",G30*Resumen!$G$6) -> 28544115 | I30: Disponible UF | L30: 0 | M30: — | N30: UF | O30: =IF(G30="","",G30*Resumen!$S$11) -> 9420.5 | P30: =IF(G30="","",(G30-G30*Resumen!$S$11)/Resumen!$S$12) -> 785.04167 | Q30: =IF(G30="","",((G30-G30*Resumen!$S$11)/Resumen!$S$12)*((1+Resumen!$S$13)*((1+Resumen!$S$13)^Resumen!$S$12-1)/Resumen!$S$13)) -> 11475.575 | R30: =IF(G30="","",O30+Q30) -> 20896.075
A31: SECTOR 1 | B31: P18 | C31: UF B | D31: 24-2-3-Ch8-P18-UFB | E31: — | F31: 513.84 | G31: =ROUND(F31*$U$6,0) -> 18841 | H31: =IF(G31="","",G31*Resumen!$G$6) -> 28544115 | I31: Disponible UF | L31: 0 | M31: — | N31: UF | O31: =IF(G31="","",G31*Resumen!$S$11) -> 9420.5 | P31: =IF(G31="","",(G31-G31*Resumen!$S$11)/Resumen!$S$12) -> 785.04167 | Q31: =IF(G31="","",((G31-G31*Resumen!$S$11)/Resumen!$S$12)*((1+Resumen!$S$13)*((1+Resumen!$S$13)^Resumen!$S$12-1)/Resumen!$S$13)) -> 11475.575 | R31: =IF(G31="","",O31+Q31) -> 20896.075
A32: SECTOR 1 | B32: P19 | C32: PARCELA MADRE | D32: 24-2-3-Ch8-P19 | H32: =IF(G32="","",G32*Resumen!$G$6) | I32: Permutada | J32: Vaccaro / ACS | L32: 0 | M32: — | N32: UF | O32: =IF(G32="","",G32*Resumen!$S$11) | P32: =IF(G32="","",(G32-G32*Resumen!$S$11)/Resumen!$S$12) | Q32: =IF(G32="","",((G32-G32*Resumen!$S$11)/Resumen!$S$12)*((1+Resumen!$S$13)*((1+Resumen!$S$13)^Resumen!$S$12-1)/Resumen!$S$13)) | R32: =IF(G32="","",O32+Q32) | S32: 2
A33: ▼ SECTOR II — Manzanas 14, 15, 16 + Quinta 2 | N33: UF
A34: SECTOR SUR - MZA 14 | B34: Mza14-P3 | C34: PARCELA MADRE | D34: 24-2-3-Mz14-P3 | E34: 1265.1 | H34: =IF(G34="","",G34*Resumen!$G$6) | I34: Disponible | L34: 0 | M34: — | N34: UF | O34: =IF(G34="","",G34*Resumen!$S$11) | P34: =IF(G34="","",(G34-G34*Resumen!$S$11)/Resumen!$S$12) | Q34: =IF(G34="","",((G34-G34*Resumen!$S$11)/Resumen!$S$12)*((1+Resumen!$S$13)*((1+Resumen!$S$13)^Resumen!$S$12-1)/Resumen!$S$13)) | R34: =IF(G34="","",O34+Q34) | S34: 2
A35: SECTOR SUR | B35: Mza14-P3 | C35: UF A | D35: 24-2-3-Mz14-P3-UFA | E35: — | F35: 632.55 | G35: =ROUND(F35*$U$6,0) -> 23194 | H35: =IF(G35="","",G35*Resumen!$G$6) -> 35138910 | I35: Disponible | L35: 0 | M35: — | N35: UF | O35: =IF(G35="","",G35*Resumen!$S$11) -> 11597 | P35: =IF(G35="","",(G35-G35*Resumen!$S$11)/Resumen!$S$12) -> 966.41667 | Q35: =IF(G35="","",((G35-G35*Resumen!$S$11)/Resumen!$S$12)*((1+Resumen!$S$13)*((1+Resumen!$S$13)^Resumen!$S$12-1)/Resumen!$S$13)) -> 14126.876 | R35: =IF(G35="","",O35+Q35) -> 25723.876
A36: SECTOR SUR | B36: Mza14-P3 | C36: UF B | D36: 24-2-3-Mz14-P3-UFB | E36: — | F36: 632.55 | G36: =ROUND(F36*$U$6,0) -> 23194 | H36: =IF(G36="","",G36*Resumen!$G$6) -> 35138910 | I36: Disponible | L36: 0 | M36: — | N36: UF | O36: =IF(G36="","",G36*Resumen!$S$11) -> 11597 | P36: =IF(G36="","",(G36-G36*Resumen!$S$11)/Resumen!$S$12) -> 966.41667 | Q36: =IF(G36="","",((G36-G36*Resumen!$S$11)/Resumen!$S$12)*((1+Resumen!$S$13)*((1+Resumen!$S$13)^Resumen!$S$12-1)/Resumen!$S$13)) -> 14126.876 | R36: =IF(G36="","",O36+Q36) -> 25723.876
A37: SECTOR SUR | B37: Mza14-P4 | C37: PARCELA MADRE | D37: 24-2-3-Mz14-P4 | E37: 904.82 | H37: =IF(G37="","",G37*Resumen!$G$6) | I37: Disponible | L37: 0 | M37: — | N37: UF | O37: =IF(G37="","",G37*Resumen!$S$11) | P37: =IF(G37="","",(G37-G37*Resumen!$S$11)/Resumen!$S$12) | Q37: =IF(G37="","",((G37-G37*Resumen!$S$11)/Resumen!$S$12)*((1+Resumen!$S$13)*((1+Resumen!$S$13)^Resumen!$S$12-1)/Resumen!$S$13)) | R37: =IF(G37="","",O37+Q37) | S37: 2
A38: SECTOR SUR | B38: Mza14-P4 | C38: UF A | D38: 24-2-3-Mz14-P4-UFA | E38: — | F38: 452.41 | G38: =ROUND(F38*$U$6,0) -> 16588 | H38: =IF(G38="","",G38*Resumen!$G$6) -> 25130820 | I38: Disponible | L38: 0 | M38: — | N38: UF | O38: =IF(G38="","",G38*Resumen!$S$11) -> 8294 | P38: =IF(G38="","",(G38-G38*Resumen!$S$11)/Resumen!$S$12) -> 691.16667 | Q38: =IF(G38="","",((G38-G38*Resumen!$S$11)/Resumen!$S$12)*((1+Resumen!$S$13)*((1+Resumen!$S$13)^Resumen!$S$12-1)/Resumen!$S$13)) -> 10103.329 | R38: =IF(G38="","",O38+Q38) -> 18397.329
A39: SECTOR SUR | B39: Mza14-P4 | C39: UF B | D39: 24-2-3-Mz14-P4-UFB | E39: — | F39: 452.41 | G39: =ROUND(F39*$U$6,0) -> 16588 | H39: =IF(G39="","",G39*Resumen!$G$6) -> 25130820 | I39: Disponible | L39: 0 | M39: — | N39: UF | O39: =IF(G39="","",G39*Resumen!$S$11) -> 8294 | P39: =IF(G39="","",(G39-G39*Resumen!$S$11)/Resumen!$S$12) -> 691.16667 | Q39: =IF(G39="","",((G39-G39*Resumen!$S$11)/Resumen!$S$12)*((1+Resumen!$S$13)*((1+Resumen!$S$13)^Resumen!$S$12-1)/Resumen!$S$13)) -> 10103.329 | R39: =IF(G39="","",O39+Q39) -> 18397.329
A40: SECTOR SUR | B40: Mza14-P5 | C40: PARCELA MADRE | D40: 24-2-3-Mz14-P5 | E40: 913.89 | H40: =IF(G40="","",G40*Resumen!$G$6) | I40: Disponible | L40: 0 | M40: — | N40: UF | O40: =IF(G40="","",G40*Resumen!$S$11) | P40: =IF(G40="","",(G40-G40*Resumen!$S$11)/Resumen!$S$12) | Q40: =IF(G40="","",((G40-G40*Resumen!$S$11)/Resumen!$S$12)*((1+Resumen!$S$13)*((1+Resumen!$S$13)^Resumen!$S$12-1)/Resumen!$S$13)) | R40: =IF(G40="","",O40+Q40) | S40: 2
A41: SECTOR SUR | B41: Mza14-P5 | C41: UF A | D41: 24-2-3-Mz14-P5-UFA | E41: — | F41: 456.95 | G41: =ROUND(F41*$U$6,0) -> 16755 | H41: =IF(G41="","",G41*Resumen!$G$6) -> 25383825 | I41: Disponible | L41: 0 | M41: — | N41: UF | O41: =IF(G41="","",G41*Resumen!$S$11) -> 8377.5 | P41: =IF(G41="","",(G41-G41*Resumen!$S$11)/Resumen!$S$12) -> 698.125 | Q41: =IF(G41="","",((G41-G41*Resumen!$S$11)/Resumen!$S$12)*((1+Resumen!$S$13)*((1+Resumen!$S$13)^Resumen!$S$12-1)/Resumen!$S$13)) -> 10205.045 | R41: =IF(G41="","",O41+Q41) -> 18582.545
...

Sheet Clientes
A1: 👥 CLIENTES DEL PROYECTO — RINCÓN DEL BOSQUE II
A2: Cargá solo: Nombre · Lote (desplegable) · Contrato N° · Total Contrato · Estado. ID, Sup., Cobrado, Saldo, Comisión y Neto se calculan solos. El Cobrado lee el FlujoCaja por la Ref. de contrato; cobros fuera del flujo van en 'Cobro manual' (col. O). El %% de comisión global está en L3.
A3: =HYPERLINK("#'Resumen'!A1","◀ Volver al Resumen") -> ◀ Volver al Resumen | K3: % Comisión → | L3: 0.03
A4: ID | B4: Apellido y Nombre | C4: DNI/CUIT | D4: Teléfono | E4: Email | F4: Lote (Nomenclatura) | G4: Sup. Lote (m²) | H4: Contrato N° | I4: Total Contrato (USD) | J4: Cobrado (USD) | K4: Saldo (USD) | L4: Comisión (USD) | M4: Neto a Dueños (USD) | N4: Estado Escritura | O4: Cobro manual (USD) | P4: % Com.
A5: =IF(B5="","",ROW()-4) -> 1 | B5: Moreira (Analia y Casi) | F5: 24-2-3-Ch8-P12 | G5: {=IFERROR(IF(INDEX(MaestroLotes!$F:$F,MATCH(F5,MaestroLotes!$D:$D,0))="",INDEX(MaestroLotes!$E:$E,MATCH(F5,MaestroLotes!$D:$D,0)),INDEX(MaestroLotes!$F:$F,MATCH(F5,MaestroLotes!$D:$D,0))),"")} -> 900 | H5: BOL-012 | I5: 28000 | J5: =IF(AND(H5="",O5=""),0,SUMIFS(FlujoCajaACTUAL!$E:$E,FlujoCajaACTUAL!$D:$D,H5)+N(O5)) -> 27160 | K5: =IF(I5="","",M5-J5) -> 0 | L5: =IF(I5="","",I5*IF(P5="",$L$3,P5)) -> 840 | M5: =IF(I5="","",I5-L5) -> 27160 | N5: Pendiente | P5: 0.03
A6: =IF(B6="","",ROW()-4) -> 2 | B6: Daddona (Luciano y Natalia) | F6: 24-2-3-Ch8-P13 | G6: {=IFERROR(IF(INDEX(MaestroLotes!$F:$F,MATCH(F6,MaestroLotes!$D:$D,0))="",INDEX(MaestroLotes!$E:$E,MATCH(F6,MaestroLotes!$D:$D,0)),INDEX(MaestroLotes!$F:$F,MATCH(F6,MaestroLotes!$D:$D,0))),"")} -> 900 | H6: BOL-013 | I6: 28000 | J6: =IF(AND(H6="",O6=""),0,SUMIFS(FlujoCajaACTUAL!$E:$E,FlujoCajaACTUAL!$D:$D,H6)+N(O6)) -> 27160 | K6: =IF(I6="","",M6-J6) -> 0 | L6: =IF(I6="","",I6*IF(P6="",$L$3,P6)) -> 840 | M6: =IF(I6="","",I6-L6) -> 27160 | N6: Pendiente | P6: 0.03
A7: =IF(B7="","",ROW()-4) -> 3 | B7: Virginia | F7: 24-2-3-Ch8-P14-UFA | G7: {=IFERROR(IF(INDEX(MaestroLotes!$F:$F,MATCH(F7,MaestroLotes!$D:$D,0))="",INDEX(MaestroLotes!$E:$E,MATCH(F7,MaestroLotes!$D:$D,0)),INDEX(MaestroLotes!$F:$F,MATCH(F7,MaestroLotes!$D:$D,0))),"")} -> 465 | H7: BOL-014A | I7: 14000 | J7: =IF(AND(H7="",O7=""),0,SUMIFS(FlujoCajaACTUAL!$E:$E,FlujoCajaACTUAL!$D:$D,H7)+N(O7)) -> 14000 | K7: =IF(I7="","",M7-J7) -> 0 | L7: =IF(I7="","",I7*IF(P7="",$L$3,P7)) -> 0 | M7: =IF(I7="","",I7-L7) -> 14000 | N7: Pendiente | P7: 0
A8: =IF(B8="","",ROW()-4) -> 4 | B8: Mariel | F8: 24-2-3-Ch8-P14-UFB | G8: {=IFERROR(IF(INDEX(MaestroLotes!$F:$F,MATCH(F8,MaestroLotes!$D:$D,0))="",INDEX(MaestroLotes!$E:$E,MATCH(F8,MaestroLotes!$D:$D,0)),INDEX(MaestroLotes!$F:$F,MATCH(F8,MaestroLotes!$D:$D,0))),"")} -> 465 | H8: BOL-014B | I8: 16500 | J8: =I8/2 -> 8250 | K8: =IF(I8="","",M8-J8) -> 7755 | L8: =IF(I8="","",I8*IF(P8="",$L$3,P8)) -> 495 | M8: =IF(I8="","",I8-L8) -> 16005 | N8: Pendiente | P8: 0.03
A9: =IF(B9="","",ROW()-4) -> 5 | B9: Michael | F9: 24-2-3-Ch8-P15-UFB | G9: {=IFERROR(IF(INDEX(MaestroLotes!$F:$F,MATCH(F9,MaestroLotes!$D:$D,0))="",INDEX(MaestroLotes!$E:$E,MATCH(F9,MaestroLotes!$D:$D,0)),INDEX(MaestroLotes!$F:$F,MATCH(F9,MaestroLotes!$D:$D,0))),"")} -> 492.5 | H9: BOL-015B | I9: 16500 | J9: 16000 | L9: =IF(I9="","",I9*IF(P9="",$L$3,P9)) -> 495 | M9: =IF(I9="","",I9-L9) -> 16005 | N9: Pendiente | P9: 0.03
J10: 0
A12: =IF(B12="","",ROW()-4) | G12: {=IFERROR(IF(INDEX(MaestroLotes!$F:$F,MATCH(F12,MaestroLotes!$D:$D,0))="",INDEX(MaestroLotes!$E:$E,MATCH(F12,MaestroLotes!$D:$D,0)),INDEX(MaestroLotes!$F:$F,MATCH(F12,MaestroLotes!$D:$D,0))),"")} | J12: =IF(AND(H12="",O12=""),0,SUMIFS(FlujoCajaACTUAL!$E:$E,FlujoCajaACTUAL!$D:$D,H12)+N(O12)) -> 0 | K12: =IF(I12="","",M12-J12) | L12: =IF(I12="","",I12*IF(P12="",$L$3,P12)) | M12: =IF(I12="","",I12-L12)
A13: =IF(B13="","",ROW()-4) | G13: {=IFERROR(IF(INDEX(MaestroLotes!$F:$F,MATCH(F13,MaestroLotes!$D:$D,0))="",INDEX(MaestroLotes!$E:$E,MATCH(F13,MaestroLotes!$D:$D,0)),INDEX(MaestroLotes!$F:$F,MATCH(F13,MaestroLotes!$D:$D,0))),"")} | J13: =IF(AND(H13="",O13=""),0,SUMIFS(FlujoCajaACTUAL!$E:$E,FlujoCajaACTUAL!$D:$D,H13)+N(O13)) -> 0 | K13: =IF(I13="","",M13-J13) | L13: =IF(I13="","",I13*IF(P13="",$L$3,P13)) | M13: =IF(I13="","",I13-L13)
A14: =IF(B14="","",ROW()-4) | G14: {=IFERROR(IF(INDEX(MaestroLotes!$F:$F,MATCH(F14,MaestroLotes!$D:$D,0))="",INDEX(MaestroLotes!$E:$E,MATCH(F14,MaestroLotes!$D:$D,0)),INDEX(MaestroLotes!$F:$F,MATCH(F14,MaestroLotes!$D:$D,0))),"")} | J14: =IF(AND(H14="",O14=""),0,SUMIFS(FlujoCajaACTUAL!$E:$E,FlujoCajaACTUAL!$D:$D,H14)+N(O14)) -> 0 | K14: =IF(I14="","",M14-J14) | L14: =IF(I14="","",I14*IF(P14="",$L$3,P14)) | M14: =IF(I14="","",I14-L14)
A15: =IF(B15="","",ROW()-4) | G15: {=IFERROR(IF(INDEX(MaestroLotes!$F:$F,MATCH(F15,MaestroLotes!$D:$D,0))="",INDEX(MaestroLotes!$E:$E,MATCH(F15,MaestroLotes!$D:$D,0)),INDEX(MaestroLotes!$F:$F,MATCH(F15,MaestroLotes!$D:$D,0))),"")} | J15: =IF(AND(H15="",O15=""),0,SUMIFS(FlujoCajaACTUAL!$E:$E,FlujoCajaACTUAL!$D:$D,H15)+N(O15)) -> 0 | K15: =IF(I15="","",M15-J15) | L15: =IF(I15="","",I15*IF(P15="",$L$3,P15)) | M15: =IF(I15="","",I15-L15)
A16: =IF(B16="","",ROW()-4) | G16: {=IFERROR(IF(INDEX(MaestroLotes!$F:$F,MATCH(F16,MaestroLotes!$D:$D,0))="",INDEX(MaestroLotes!$E:$E,MATCH(F16,MaestroLotes!$D:$D,0)),INDEX(MaestroLotes!$F:$F,MATCH(F16,MaestroLotes!$D:$D,0))),"")} | J16: =IF(AND(H16="",O16=""),0,SUMIFS(FlujoCajaACTUAL!$E:$E,FlujoCajaACTUAL!$D:$D,H16)+N(O16)) -> 0 | K16: =IF(I16="","",M16-J16) | L16: =IF(I16="","",I16*IF(P16="",$L$3,P16)) | M16: =IF(I16="","",I16-L16)
A17: =IF(B17="","",ROW()-4) | G17: {=IFERROR(IF(INDEX(MaestroLotes!$F:$F,MATCH(F17,MaestroLotes!$D:$D,0))="",INDEX(MaestroLotes!$E:$E,MATCH(F17,MaestroLotes!$D:$D,0)),INDEX(MaestroLotes!$F:$F,MATCH(F17,MaestroLotes!$D:$D,0))),"")} | J17: =IF(AND(H17="",O17=""),0,SUMIFS(FlujoCajaACTUAL!$E:$E,FlujoCajaACTUAL!$D:$D,H17)+N(O17)) -> 0 | K17: =IF(I17="","",M17-J17) | L17: =IF(I17="","",I17*IF(P17="",$L$3,P17)) | M17: =IF(I17="","",I17-L17)
A18: =IF(B18="","",ROW()-4) | G18: {=IFERROR(IF(INDEX(MaestroLotes!$F:$F,MATCH(F18,MaestroLotes!$D:$D,0))="",INDEX(MaestroLotes!$E:$E,MATCH(F18,MaestroLotes!$D:$D,0)),INDEX(MaestroLotes!$F:$F,MATCH(F18,MaestroLotes!$D:$D,0))),"")} | J18: =IF(AND(H18="",O18=""),0,SUMIFS(FlujoCajaACTUAL!$E:$E,FlujoCajaACTUAL!$D:$D,H18)+N(O18)) -> 0 | K18: =IF(I18="","",M18-J18) | L18: =IF(I18="","",I18*IF(P18="",$L$3,P18)) | M18: =IF(I18="","",I18-L18)
A19: =IF(B19="","",ROW()-4) | G19: {=IFERROR(IF(INDEX(MaestroLotes!$F:$F,MATCH(F19,MaestroLotes!$D:$D,0))="",INDEX(MaestroLotes!$E:$E,MATCH(F19,MaestroLotes!$D:$D,0)),INDEX(MaestroLotes!$F:$F,MATCH(F19,MaestroLotes!$D:$D,0))),"")} | J19: =IF(AND(H19="",O19=""),0,SUMIFS(FlujoCajaACTUAL!$E:$E,FlujoCajaACTUAL!$D:$D,H19)+N(O19)) -> 0 | K19: =IF(I19="","",M19-J19) | L19: =IF(I19="","",I19*IF(P19="",$L$3,P19)) | M19: =IF(I19="","",I19-L19)
A20: =IF(B20="","",ROW()-4) | G20: {=IFERROR(IF(INDEX(MaestroLotes!$F:$F,MATCH(F20,MaestroLotes!$D:$D,0))="",INDEX(MaestroLotes!$E:$E,MATCH(F20,MaestroLotes!$D:$D,0)),INDEX(MaestroLotes!$F:$F,MATCH(F20,MaestroLotes!$D:$D,0))),"")} | J20: =IF(AND(H20="",O20=""),0,SUMIFS(FlujoCajaACTUAL!$E:$E,FlujoCajaACTUAL!$D:$D,H20)+N(O20)) -> 0 | K20: =IF(I20="","",M20-J20) | L20: =IF(I20="","",I20*IF(P20="",$L$3,P20)) | M20: =IF(I20="","",I20-L20)
A21: =IF(B21="","",ROW()-4) | G21: {=IFERROR(IF(INDEX(MaestroLotes!$F:$F,MATCH(F21,MaestroLotes!$D:$D,0))="",INDEX(MaestroLotes!$E:$E,MATCH(F21,MaestroLotes!$D:$D,0)),INDEX(MaestroLotes!$F:$F,MATCH(F21,MaestroLotes!$D:$D,0))),"")} | J21: =IF(AND(H21="",O21=""),0,SUMIFS(FlujoCajaACTUAL!$E:$E,FlujoCajaACTUAL!$D:$D,H21)+N(O21)) -> 0 | K21: =IF(I21="","",M21-J21) | L21: =IF(I21="","",I21*IF(P21="",$L$3,P21)) | M21: =IF(I21="","",I21-L21)
A22: =IF(B22="","",ROW()-4) | G22: {=IFERROR(IF(INDEX(MaestroLotes!$F:$F,MATCH(F22,MaestroLotes!$D:$D,0))="",INDEX(MaestroLotes!$E:$E,MATCH(F22,MaestroLotes!$D:$D,0)),INDEX(MaestroLotes!$F:$F,MATCH(F22,MaestroLotes!$D:$D,0))),"")} | J22: =IF(AND(H22="",O22=""),0,SUMIFS(FlujoCajaACTUAL!$E:$E,FlujoCajaACTUAL!$D:$D,H22)+N(O22)) -> 0 | K22: =IF(I22="","",M22-J22) | L22: =IF(I22="","",I22*IF(P22="",$L$3,P22)) | M22: =IF(I22="","",I22-L22)
A23: =IF(B23="","",ROW()-4) | G23: {=IFERROR(IF(INDEX(MaestroLotes!$F:$F,MATCH(F23,MaestroLotes!$D:$D,0))="",INDEX(MaestroLotes!$E:$E,MATCH(F23,MaestroLotes!$D:$D,0)),INDEX(MaestroLotes!$F:$F,MATCH(F23,MaestroLotes!$D:$D,0))),"")} | J23: =IF(AND(H23="",O23=""),0,SUMIFS(FlujoCajaACTUAL!$E:$E,FlujoCajaACTUAL!$D:$D,H23)+N(O23)) -> 0 | K23: =IF(I23="","",M23-J23) | L23: =IF(I23="","",I23*IF(P23="",$L$3,P23)) | M23: =IF(I23="","",I23-L23)
... A34: =IF(B34="","",ROW()-4) | G34: {=IFERROR(IF(INDEX(MaestroLotes!$F:$F,MATCH(F34,MaestroLotes!$D:$D,0))="",INDEX(MaestroLotes!$E:$E,MATCH(F34,MaestroLotes!$D:$D,0)),INDEX(MaestroLotes!$F:$F,MATCH(F34,MaestroLotes!$D:$D,0))),"")} | J34: =IF(AND(H34="",O34=""),0,SUMIFS(FlujoCajaACTUAL!$E:$E,FlujoCajaACTUAL!$D:$D,H34)+N(O34)) -> 0 | K34: =IF(I34="","",M34-J34) | L34: =IF(I34="","",I34*IF(P34="",$L$3,P34)) | M34: =IF(I34="","",I34-L34)
A35: TOTALES | I35: =SUM(I5:I34) -> 103000 | J35: =SUM(J5:J34) -> 92570 | K35: =SUM(K5:K34) -> 7755 | L35: =SUM(L5:L34) -> 2670 | M35: =SUM(M5:M34) -> 100330

Sheet DetalleCostos
A1: 🧾 DETALLE DE COSTOS — RDB II · PRESUPUESTO, ABONADO Y SALDO
A2: Cargá el monto abonado y el saldo se descuenta solo · plantilla libre (los totales suman siempre)
A3: =HYPERLINK("#'Resumen'!A1","◀ Volver al Resumen") -> ◀ Volver al Resumen
A4: Rubro / Concepto | B4: Ruta 16 (USD) | C4: Sector Sur (USD) | D4: Mangrullo (USD) | E4: TOTAL 100% (USD) | F4: Permuta (USD) | G4: Efectivo a pagar (USD) | H4: Abonado (USD) | I4: Saldo Pendiente (USD) | J4: Comentario
A5: ▼ INFRAESTRUCTURA — POR SECTOR (Ruta 16 · Sector Sur · Mangrullo)
A6: Materiales energía eléctrica | B6: 17000 | C6: 28000 | D6: 35000 | E6: =N(B6)+N(C6)+N(D6) -> 80000 | F6: 30000 | G6: =E6-F6 -> 50000 | H6: 17000 | I6: =IF(G6="","",N(G6)-N(H6)) -> 33000 | J6: Transformadores, cableado
A7: Mano de obra redes de servicios | B7: 40500 | C7: 75800 | D7: 28200 | E7: =N(B7)+N(C7)+N(D7) -> 144500 | F7: 70000 | G7: =E7-F7 -> 74500 | H7: 25500 | I7: =IF(G7="","",N(G7)-N(H7)) -> 49000 | J7: Tendido de redes
A8: Mano de obra limpieza + camino | B8: 25000 | C8: 25000 | D8: 25000 | E8: =N(B8)+N(C8)+N(D8) -> 75000 | F8: =IF(E8="","",N(E8)-N(G8)) -> 30000 | G8: 45000 | H8: 10000 | I8: =IF(G8="","",N(G8)-N(H8)) -> 35000 | J8: Apertura, destronque, ripio
A9: ▼ OTROS COSTOS Y RESERVAS (agregá lo que necesites)
A10: Reserva general de proyecto | E10: =G10 -> 50000 | F10: =IF(E10="","",N(E10)-N(G10)) -> 0 | G10: 50000 | H10: 25000 | I10: =IF(G10="","",N(G10)-N(H10)) -> 25000 | J10: Reserva / imprevistos
A11: Ajuste s/ presupuesto original | E11: =G11 -> 5650 | F11: =IF(E11="","",N(E11)-N(G11)) -> 0 | G11: 5650 | H11: 0 | I11: =IF(G11="","",N(G11)-N(H11)) -> 5650 | J11: Diferencia detectada
F12: =IF(E12="","",N(E12)-N(G12))
A13: Curva de certificación de obra (%) SII | B13: 0.25 | C13: 0.25 | D13: 0.25 | E13: 0.25 | K13: 0 | L13: 0 | M13: 0 | N13: 0 | O13: 0 | P13: 0 | Q13: 0 | R13: 0 | S13: 0 | T13: 1
A14: Materiales energía eléctrica | B14: =C6*B13 -> 7000 | C14: =B14 -> 7000 | D14: =B14 -> 7000 | E14: =C14 -> 7000 | F14: =SUM(B14:E14) -> 28000 | I14: =IF(G14="","",N(G14)-N(H14))
A15: Mano de obra redes de servicios | B15: =I7*B13 -> 12250 | C15: 12250 | D15: 12250 | E15: 12250 | F15: =SUM(B15:E15) -> 49000 | I15: =IF(G15="","",N(G15)-N(H15))
A16: Mano de obra limpieza + camino | B16: =I8*B13 -> 8750 | C16: 8750 | D16: 8750 | E16: 8750 | F16: =SUM(B16:E16) -> 35000 | I16: =IF(G16="","",N(G16)-N(H16))
F17: =IF(E17="","",N(E17)-N(G17)) | I17: =IF(G17="","",N(G17)-N(H17))
F18: =IF(E18="","",N(E18)-N(G18)) | I18: =IF(G18="","",N(G18)-N(H18))
F19: =IF(E19="","",N(E19)-N(G19)) | I19: =IF(G19="","",N(G19)-N(H19))
F20: =IF(E20="","",N(E20)-N(G20)) | I20: =IF(G20="","",N(G20)-N(H20))
F21: =IF(E21="","",N(E21)-N(G21)) | I21: =IF(G21="","",N(G21)-N(H21))
A22: TOTALES (presupuesto · permuta · efectivo · abonado · saldo) | E22: =SUM(E5:E21) -> 383150.25 | F22: =SUM(F5:F21) -> 242000 | G22: =SUM(G5:G21) -> 225150 | H22: =SUM(H5:H21) -> 77500 | I22: =SUM(I5:I21) -> 147650
A23: Permuta equivalente en lotes (a USD 30.000 c/u): | F23: =TEXT(F22/30000,"0.0")&" lotes" -> 8.1 lotes | I23: =I22/30000 -> 4.9216667 | J23: 9

Sheet FlujoCajaACTUAL
A1: 💰 FLUJO DE CAJA DEL PROYECTO
A2: Movimientos de ingreso y egreso EXCLUSIVOS de Rincón del Bosque II
A3: =HYPERLINK("#'Resumen'!A1","◀ Volver al Resumen") -> ◀ Volver al Resumen | D3: ="Ingresos: $"&TEXT(SUM(E5:E101),"#,##0")&" | Egresos: $"&TEXT(SUM(F5:F101),"#,##0")&" | Saldo: $"&TEXT(SUM(E5:E101)-SUM(F5:F101),"#,##0") -> Ingresos: $91,600 | Egresos: $77,574 | Saldo: $14,026
A4: Fecha | B4: Concepto | C4: Tipo | D4: Contrato / Ref. | E4: Ingreso (USD) | F4: Egreso (USD)
B5: Venta parcela completa - Moreira (P12) — NETO a dueños | C5: Cobro Cliente | D5: BOL-012 | E5: 27160
B6: Venta parcela completa - Daddona (P13) — NETO a dueños | C6: Cobro Cliente | D6: BOL-013 | E6: 27160
B7: Venta media parcela (UF) - Virginia (P14-UFA) — NETO a dueños | C7: Cobro Cliente | D7: BOL-014A | E7: 14000
B8: Venta media parcela (UF) - Mariel (P14-UFB) - 50% a cuenta — NETO a dueños | C8: Cobro Cliente | D8: BOL-014B | E8: 7760
B9: Venta media parcela (UF) - Michael (P15-UFB) - completo — NETO a dueños | C9: Cobro Cliente | D9: BOL-015B | E9: 15520
B13: RESUMEN ANTERIOR
B14: Estudio ambiental (RDB I + II) | C14: Gasto General | D14: AMB | F14: 5600
B15: Planos redes de servicios | C15: Gasto General | D15: PLAN | F15: 2920
B16: Alquiler 35 hs retroexcavadora | C16: Gasto General | D16: MAQ | F16: 2250
B17: Contrato personal volteo y limpieza (1) | C17: Pago Contratista | D17: LIMP1 | F17: 1100
B18: Contrato personal volteo y limpieza (2) | C18: Pago Contratista | D18: LIMP2 | F18: 1364
B19: Limpieza semana 1 (ARS 490,000 @ 1420) | C19: Gasto General | D19: PESOS | F19: 345
B20: Limpieza semana 2 (ARS 598,000 @ 1420) | C20: Gasto General | D20: PESOS | F20: 421
B21: Limpieza semana 3 (ARS 1,016,300 @ 1420) | C21: Gasto General | D21: PESOS | F21: 716
B22: Limpieza semana 4 (ARS 800,000 @ 1420) | C22: Gasto General | D22: PESOS | F22: 563
B23: Limpieza semana 5 (ARS 640,000 @ 1420) | C23: Gasto General | D23: PESOS | F23: 451
B24: Limpieza semana 6 (ARS 498,730 @ 1420) | C24: Gasto General | D24: PESOS | F24: 351
B25: Limpieza semana 7 (ARS 380,000 @ 1420) | C25: Gasto General | D25: PESOS | F25: 268
... B38: Compra materiales sistema contra incendio (monto a completar) | C38: Pago Contratista | D38: INFRA-AGUA | F38: 300
B39: SECTOR II — Materiales y mano de obra perforación
B40: Materiales corralón (Pilares grueso, cemento, hierro del 8, 6, anticongelante, ladrillo) | C40: Pago Proveedor | F40: =(4063000+180000+18703+4200)/1490 -> 2863.0221
B43: SALDO DISPONIBLE 14.162 EN:
B44: NICO | C44: =14162-C45 -> 8829
B45: ANA | C45: 5333
E48: =Clientes!M12
A102: TOTALES DEL PERÍODO | E102: =SUM(E5:E101) -> 91600 | F102: =SUM(F5:F101) -> 77574.022

Sheet FlujodeCaja FUTURO
A1: 💰 FLUJO DE CAJA DEL PROYECTO
A2: Movimientos de ingreso y egreso EXCLUSIVOS de Rincón del Bosque II
A3: =HYPERLINK("#'Resumen'!A1","◀ Volver al Resumen") -> ◀ Volver al Resumen | D3: ="Ingresos: $"&TEXT(SUM(E5:E101),"#,##0")&" | Egresos: $"&TEXT(SUM(F5:F101),"#,##0")&" | Saldo: $"&TEXT(SUM(E5:E101)-SUM(F5:F101),"#,##0") -> Ingresos: $132,145 | Egresos: $122,366 | Saldo: $9,779
A4: Fecha | B4: Concepto | C4: Tipo | D4: Contrato / Ref. | E4: Ingreso (USD) | F4: Egreso (USD)
B5: Venta parcela completa - Moreira (P12) — NETO a dueños | C5: Cobro Cliente | D5: BOL-012 | E5: 27160
B6: Venta parcela completa - Daddona (P13) — NETO a dueños | C6: Cobro Cliente | D6: BOL-013 | E6: 27160
B7: Venta media parcela (UF) - Virginia (P14-UFA) — NETO a dueños | C7: Cobro Cliente | D7: BOL-014A | E7: 14000
B8: Venta media parcela (UF) - Mariel (P14-UFB) - 50% a cuenta — NETO a dueños | C8: Cobro Cliente | D8: BOL-014B | E8: 7760
B9: Venta media parcela (UF) - Michael (P15-UFB) - NETO a dueños | C9: Cobro Cliente | D9: BOL-015B | E9: 15520
A10: 46204 | B10: Venta media parcela (UF) - Santoro (P15-UFA) - NETO a dueños | C10: Cobro Cliente | D10: BOL-015B | E10: 10475
A11: 46204 | B11: Venta parcela completa - Leonardo Ariel - | C11: Cobro Cliente | D11: BOL-015B | E11: 30070
B13: RESUMEN ANTERIOR
B14: Estudio ambiental (RDB I + II) | C14: Gasto General | D14: AMB | F14: 5600
B15: Planos redes de servicios | C15: Gasto General | D15: PLAN | F15: 2920
B16: Alquiler 35 hs retroexcavadora | C16: Gasto General | D16: MAQ | F16: 2250
B17: Contrato personal volteo y limpieza (1) | C17: Pago Contratista | D17: LIMP1 | F17: 1100
B18: Contrato personal volteo y limpieza (2) | C18: Pago Contratista | D18: LIMP2 | F18: 1364
B19: Limpieza semana 1 (ARS 490,000 @ 1420) | C19: Gasto General | D19: PESOS | F19: 345
B20: Limpieza semana 2 (ARS 598,000 @ 1420) | C20: Gasto General | D20: PESOS | F20: 421
B21: Limpieza semana 3 (ARS 1,016,300 @ 1420) | C21: Gasto General | D21: PESOS | F21: 716
B22: Limpieza semana 4 (ARS 800,000 @ 1420) | C22: Gasto General | D22: PESOS | F22: 563
B23: Limpieza semana 5 (ARS 640,000 @ 1420) | C23: Gasto General | D23: PESOS | F23: 451
B24: Limpieza semana 6 (ARS 498,730 @ 1420) | C24: Gasto General | D24: PESOS | F24: 351
B25: Limpieza semana 7 (ARS 380,000 @ 1420) | C25: Gasto General | D25: PESOS | F25: 268
... B36: Caminos y limpieza - 50% 2do restante (Sector I + Sector 2 etapa 1) | C36: Pago Contratista | D36: INFRA-CAM2 | F36: 5750
B37: Pago arena utilizada S1 (monto a completar) | C37: Pago Proveedor | D37: SDAS | F37: ?
B39: SECTOR II — Materiales y mano de obra perforación
B40: Perforación pozo profundo mano de obra y materiales (etapa 1, perforación y encamizado). | C40: Pago Contratista | F40: 6420
B41: Materiales extensión red de agua Sector 2 + 3 | C41: Pago Proveedor | F41: 6528
B42: Materiales corralón Sector 1 (Pilares grueso, cemento, hierro del 8, 6, anticongelante, ladrillo) | C42: Pago Proveedor | F42: =3827800/Resumen!G6 -> 2526.6007
B43: Adelanto 20% Extensión redes de servicios básicos (luz y agua) | C43: Pago Contratista | F43: =DetalleCostos!B15 -> 12250
B44: Adelanto 35 % Camino (condición contrato base). | C44: Pago Contratista | F44: 7480
B46: Adelanto 20% Extensión redes de servicios básicos (luz y agua) | F46: =F43 -> 12250
B47: Saldo 50% camino, total
E48: =Clientes!M12
A102: TOTALES DEL PERÍODO | E102: =SUM(E5:E101) -> 132145 | F102: =SUM(F5:F101) -> 122365.6

Sheet ComputoPrivadoNico
A1: CÓMPUTO — CONCILIACIÓN DE M² PERMUTADOS (VACCARO GESTIÓN + ACS)
A2: Derecho total 10.800 m² · Vaccaro Gestión: 5 × 1.800 = 9.000 · ACS por servicios: 2 × 900 = 1.800
A4: ▼ 1) DERECHOS ACORDADOS
A5: Concepto | E5: Cantidad | F5: Sup. unit. | G5: Total m²
A6: Vaccaro Gestión | E6: 5 | F6: 1,800 m² | G6: 9,000.00 m²
A7: ACS por ejecución de servicios | E7: 2 | F7: 900 m² | G7: 1,800.00 m²
A8: DERECHO TOTAL | G8: 10,800.00 m²
A10: ▼ 2) YA APLICADOS AL CÓMPUTO (vendidos/entregados)
A11: Nomenclatura | C11: Descripción | F11: m² aplicados | G11: Destino
A12: 24-2-3-Ch8-P11 | C12: Chacra 8 - Parcela 11 (completa) | F12: 904.51 m² | G12: Vaccaro Gestión
A13: 24-2-3-Mz15-P1-FR | C13: Mza15-P1 frente ruta (fracción) | F13: 1,858.51 m²
A14: TOTAL YA APLICADO
A16: ▼ 3) SALDO DEL DERECHO POR APLICAR
A17: Derecho total − Ya aplicado = | G17: 8,941.49 m²
A19: ▼ 4) PARCELAS ACTUALMENTE EN PODER DE VACCARO/ACS
A20: Nomenclatura | C20: Detalle | F20: m² | G20: Destino
A21: 24-2-3-Ch8-P19 | C21: Chacra 8 - P19 (madre) | F21: 1,603.05 m² | G21: Vaccaro ACS
A22: 24-2-3-Mz15-P1-FO | C22: Mza15-P1 fondo (resto) | F22: 900.00 m² | G22: Vaccaro Gestión
A24: 24-2-3-Mz15-P8 | C24: Mza15-P8 + canal (completa) | F24: 900.00 m² | G24: Vaccaro Gestión
A25: 24-2-3-Mz16-P1 | C25: Mza16-P1 (madre) | F25: 1,854.30 m² | G25: Vaccaro Gestión
A26: 24-2-3-Qt2-P8 | C26: Quinta 2 - P8 (madre) | F26: 1,818.11 m² | G26: Vaccaro Gestión
A27: 24-2-3-Mz13-P9 | C27: Mangrullo Este - Mza13-P9 (madre) | F27: 1,800.04 m² | G27: Vaccaro Gestión
A29: TOTAL EN PODER | F29: 8,875.50 m²
A31: ▼ 5) CONCILIACIÓN
A32: En poder − Saldo del derecho = | G32: -65.99 m²
A33: Total permutado (P11 + P19 + Mz15-P1 + Qt2-P8 + Mz16-P1 + Mz13-P9 + Mz13-P8) | E33: =904.51+1603.05+1854.3+1818.11+1854.3+1800.04+1721.69 -> 11556
A34: Cobro acordado Nico: 5 parcelas de 1.800 m² (las 5 VACCARO GESTIÓN) | E34: 9000
A35: ACS por ejecución de servicios (P19 1.603,05 + 196,95 de P11) | E35: 1800
A36: SALDO SIN ASIGNAR (707,56 de P11 + 48,44 exced.) | E36: =E33-E34-E35 -> 756 | F36: fracción más cercana: UF Mza14-P7 (632,70 m²)
